<mujoco model="stupid_clow">

<compiler angle="radian" eulerseq="XYZ" />

<asset>

<!-- 修改 mesh 名称为英文，并确保文件路径正确 -->

<mesh name="leftclaw" file="meshes/left_claw.stl" scale="0.001 0.001 0.001" />

<mesh name="rightclaw" file="meshes/right_claw.stl" scale="0.001 0.001 0.001" />

<mesh name="base" file="meshes/base.stl" scale="0.001 0.001 0.001" />
<!-- 定义纹理和材质 -->
    <texture type="skybox" builtin="gradient" rgb1="0.3 0.5 0.7" rgb2="0 0 0" width="512" height="3072"/>
    <texture type="2d" name="groundplane" builtin="checker" mark="edge" rgb1="0.2 0.3 0.4" rgb2="0.1 0.2 0.3"
        markrgb="0.8 0.8 0.8" width="300" height="300"/>
    <material name="groundplane" texture="groundplane" texuniform="true" texrepeat="5 5" reflectance="0.2"/>
</asset>

<worldbody>
    <!-- 定义光源 -->
    <light directional="true" pos="-0.5 0.5 3" dir="0 0 -1" />
    <!-- 地面定义：水平平面，法向量 (0, 0, 1)，位于 z=0，使用 groundplane 材质 -->
    <geom name="floor" type="plane" size="0.5 0.5 0.5" material="groundplane" />


    <body name="rightclaw" pos="0.1740519959215726 -0.09990390285707751 -0.18522088237902026" euler="-1.755601551209688 1.0371669501560832 -1.784603678448117">
        <joint name="rotate_joint_1" type="hinge" axis="1.0 2.8330734617026327e-15 1.3725726970351087e-15" pos="0.04499999999998194 2.6663968234579005e-07 0.005000206320415307" />
        <geom name="rightclaw_geom" type="mesh" mesh="rightclaw" pos="0 0 0" euler="0 0 0" />
        <inertial mass="0.2682109537904417" pos="-0.22369672195460671 0.015015422054442992 -0.16503978595574245" fullinertia="0.0002393085223677281 0.00047048538337556744 0.0003277113056794153 -4.1156629272337604e-05 -1.3248538640026729e-05 -4.224271645599178e-06" />
    <body name="base" pos="-0.1667966640688897 0.0059609249654490335 -0.20424725366346583" euler="-3.1415926535896332 -1.4626568336941166 3.1415926535896315">
        <geom name="base_geom" type="mesh" mesh="base" pos="0 0 0" euler="0 0 0" />
        <inertial mass="3.269907041952238" pos="0.045000000000000005 -0.02000000000000001 -0.02094710018992732" fullinertia="0.0025874418267727043 0.0031408355591143527 0.0038609807742938833 -1.4090668817825036e-18 -1.155605703797015e-18 6.505213034913027e-19" />
    <body name="leftclaw" pos="0.1862008929638116 -0.07993679244437184 -0.18885737478952788" euler="3.141592653589793 1.4626568336941197 3.1415926535897767">
        <joint name="rotate_joint_2" type="hinge" axis="-0.10792884972830213 2.064379030263944e-14 0.9941586208429363" pos="-0.16743029054881559 0.03993688254317258 -0.1149428765558054" />
        <geom name="leftclaw_geom" type="mesh" mesh="leftclaw" pos="0 0 0" euler="0 0 0" />
        <inertial mass="0.2682109537904417" pos="-0.22369672195460727 0.015015422054443006 -0.16503978595574256" fullinertia="0.0002393085223677437 0.0004704853833755494 0.0003277113056793908 -4.115662927234129e-05 -1.3248538640027762e-05 -4.224271645599436e-06" />
    </body>
    </body>
    </body>
</worldbody>
</mujoco>